[2025-02-05T13:39:22.814+0000] {local_task_job_runner.py:120} INFO - ::group::Pre task execution logs
[2025-02-05T13:39:22.833+0000] {taskinstance.py:2076} INFO - Dependencies all met for dep_context=non-requeueable deps ti=<TaskInstance: dag_dbt-model_credit_fraud.model_credit_fraud.stg_credit_fraud_run scheduled__2025-02-04T04:00:00+00:00 [queued]>
[2025-02-05T13:39:22.845+0000] {taskinstance.py:2076} INFO - Dependencies all met for dep_context=requeueable deps ti=<TaskInstance: dag_dbt-model_credit_fraud.model_credit_fraud.stg_credit_fraud_run scheduled__2025-02-04T04:00:00+00:00 [queued]>
[2025-02-05T13:39:22.846+0000] {taskinstance.py:2306} INFO - Starting attempt 1 of 1
[2025-02-05T13:39:22.861+0000] {taskinstance.py:2330} INFO - Executing <Task(DbtRunLocalOperator): model_credit_fraud.stg_credit_fraud_run> on 2025-02-04 04:00:00+00:00
[2025-02-05T13:39:22.868+0000] {standard_task_runner.py:63} INFO - Started process 4274 to run task
[2025-02-05T13:39:22.873+0000] {standard_task_runner.py:90} INFO - Running: ['***', 'tasks', 'run', 'dag_dbt-model_credit_fraud', 'model_credit_fraud.stg_credit_fraud_run', 'scheduled__2025-02-04T04:00:00+00:00', '--job-id', '125', '--raw', '--subdir', 'DAGS_FOLDER/dag_dbt-model_fraud_credit.py', '--cfg-path', '/tmp/tmp6p_bqjra']
[2025-02-05T13:39:22.874+0000] {standard_task_runner.py:91} INFO - Job 125: Subtask model_credit_fraud.stg_credit_fraud_run
[2025-02-05T13:39:22.941+0000] {task_command.py:426} INFO - Running <TaskInstance: dag_dbt-model_credit_fraud.model_credit_fraud.stg_credit_fraud_run scheduled__2025-02-04T04:00:00+00:00 [running]> on host 98025f4a542d
[2025-02-05T13:39:23.050+0000] {taskinstance.py:2648} INFO - Exporting env vars: AIRFLOW_CTX_DAG_OWNER='***' AIRFLOW_CTX_DAG_ID='dag_dbt-model_credit_fraud' AIRFLOW_CTX_TASK_ID='model_credit_fraud.stg_credit_fraud_run' AIRFLOW_CTX_EXECUTION_DATE='2025-02-04T04:00:00+00:00' AIRFLOW_CTX_TRY_NUMBER='1' AIRFLOW_CTX_DAG_RUN_ID='scheduled__2025-02-04T04:00:00+00:00'
[2025-02-05T13:39:23.053+0000] {taskinstance.py:430} INFO - ::endgroup::
[2025-02-05T13:39:25.815+0000] {local.py:220} INFO - dbtRunner is available. Using dbtRunner for invoking dbt.
[2025-02-05T13:39:25.819+0000] {local.py:436} INFO - Cloning project to writable temp directory /tmp/tmpbfkj_czb from /usr/local/airflow/dags/dbt/localiza_dw
[2025-02-05T13:39:25.831+0000] {local.py:447} INFO - Partial parse is enabled and the latest partial parse file is /tmp/cosmos/dag_dbt-model_credit_fraud__model_credit_fraud/target/partial_parse.msgpack
[2025-02-05T13:39:25.844+0000] {config.py:348} INFO - Profile caching is enable.
[2025-02-05T13:39:25.857+0000] {base.py:84} INFO - Using connection ID '***' for task execution.
[2025-02-05T13:39:25.859+0000] {base.py:244} INFO - Using real values for profile ***
[2025-02-05T13:39:25.863+0000] {config.py:335} INFO - Profile not found in cache storing and using profile: /tmp/cosmos/profile/bdc35343eb23031ee554202b16407e794194afcc614f7ea62bc658c63495a211/profiles.yml.
[2025-02-05T13:39:25.864+0000] {local.py:408} INFO - Trying to run dbtRunner with:
 ['run', '--models', 'stg_credit_fraud', '--project-dir', '/tmp/tmpbfkj_czb', '--profiles-dir', '/tmp/cosmos/profile/bdc35343eb23031ee554202b16407e794194afcc614f7ea62bc658c63495a211', '--profile', '***', '--target', 'prod']
 in /tmp/tmpbfkj_czb
[2025-02-05T13:39:25.894+0000] {logging_mixin.py:188} INFO - 13:39:25  Running with dbt=1.6.1
[2025-02-05T13:39:26.049+0000] {logging_mixin.py:188} INFO - 13:39:26  Registered adapter: postgres=1.6.1
[2025-02-05T13:39:26.084+0000] {logging_mixin.py:188} INFO - 13:39:26  Unable to do partial parsing because profile has changed
[2025-02-05T13:39:26.086+0000] {logging_mixin.py:188} INFO - 13:39:26  Unable to do partial parsing because env vars used in profiles.yml have changed
[2025-02-05T13:39:27.780+0000] {logging_mixin.py:188} INFO - 13:39:27  Found 4 models, 1 snapshot, 4 seeds, 5 tests, 3 sources, 0 exposures, 0 metrics, 349 macros, 0 groups, 0 semantic models
[2025-02-05T13:39:27.785+0000] {logging_mixin.py:188} INFO - 13:39:27
[2025-02-05T13:39:27.892+0000] {logging_mixin.py:188} INFO - 13:39:27  Concurrency: 1 threads (target='prod')
[2025-02-05T13:39:27.893+0000] {logging_mixin.py:188} INFO - 13:39:27
[2025-02-05T13:39:27.898+0000] {logging_mixin.py:188} INFO - 13:39:27  1 of 1 START sql view model dm_credit_operations.stg_credit_fraud .............. [RUN]
[2025-02-05T13:39:27.973+0000] {logging_mixin.py:188} INFO - 13:39:27  1 of 1 ERROR creating sql view model dm_credit_operations.stg_credit_fraud ..... [ERROR in 0.07s]
[2025-02-05T13:39:27.990+0000] {logging_mixin.py:188} INFO - 13:39:27
[2025-02-05T13:39:27.991+0000] {logging_mixin.py:188} INFO - 13:39:27  Finished running 1 view model in 0 hours 0 minutes and 0.20 seconds (0.20s).
[2025-02-05T13:39:28.005+0000] {logging_mixin.py:188} INFO - 13:39:28
[2025-02-05T13:39:28.007+0000] {logging_mixin.py:188} INFO - 13:39:28  Completed with 1 error and 0 warnings:
[2025-02-05T13:39:28.008+0000] {logging_mixin.py:188} INFO - 13:39:28
[2025-02-05T13:39:28.009+0000] {logging_mixin.py:188} INFO - 13:39:28  Database Error in model stg_credit_fraud (models/staging/credit_fraud/stg_credit_fraud.sql)
[2025-02-05T13:39:28.011+0000] {logging_mixin.py:188} INFO - 13:39:28    relation "dm_credit_operations_stage.raw_credit_fraud" does not exist
[2025-02-05T13:39:28.012+0000] {logging_mixin.py:188} INFO - 13:39:28    LINE 8:     select * from "***"."dm_credit_operations_stage"...
[2025-02-05T13:39:28.013+0000] {logging_mixin.py:188} INFO - 13:39:28                              ^
[2025-02-05T13:39:28.014+0000] {logging_mixin.py:188} INFO - 13:39:28    compiled Code at target/run/***/models/staging/credit_fraud/stg_credit_fraud.sql
[2025-02-05T13:39:28.016+0000] {logging_mixin.py:188} INFO - 13:39:28
[2025-02-05T13:39:28.018+0000] {logging_mixin.py:188} INFO - 13:39:28  Done. PASS=0 WARN=0 ERROR=1 SKIP=0 TOTAL=1
[2025-02-05T13:39:29.270+0000] {local.py:138} WARNING - Artifact schema version: https://schemas.getdbt.com/dbt/manifest/v10.json is above dbt-ol supported version 7. This might cause errors.
[2025-02-05T13:39:29.274+0000] {local.py:494} INFO - Inlets: []
[2025-02-05T13:39:29.275+0000] {local.py:495} INFO - Outlets: []
[2025-02-05T13:39:29.275+0000] {local.py:595} INFO - Assigning inlets/outlets without DatasetAlias
[2025-02-05T13:39:29.276+0000] {dag.py:3096} INFO - Sync 1 DAGs
[2025-02-05T13:39:29.305+0000] {dag.py:3954} INFO - Setting next_dagrun for dag_dbt-model_credit_fraud to 2025-02-05 04:00:00+00:00, run_after=2025-02-06 04:00:00+00:00
[2025-02-05T13:39:29.337+0000] {taskinstance.py:441} INFO - ::group::Post task execution logs
[2025-02-05T13:39:29.348+0000] {taskinstance.py:2905} ERROR - Task failed with exception
Traceback (most recent call last):
  File "/usr/local/lib/python3.11/site-packages/airflow/models/taskinstance.py", line 465, in _execute_task
    result = _execute_callable(context=context, **execute_callable_kwargs)
             ^^^^^^^^^^^^^^^^^^^^^^^^^^^^^^^^^^^^^^^^^^^^^^^^^^^^^^^^^^^^^
  File "/usr/local/lib/python3.11/site-packages/airflow/models/taskinstance.py", line 432, in _execute_callable
    return execute_callable(context=context, **execute_callable_kwargs)
           ^^^^^^^^^^^^^^^^^^^^^^^^^^^^^^^^^^^^^^^^^^^^^^^^^^^^^^^^^^^^
  File "/usr/local/lib/python3.11/site-packages/airflow/models/baseoperator.py", line 400, in wrapper
    return func(self, *args, **kwargs)
           ^^^^^^^^^^^^^^^^^^^^^^^^^^^
  File "/usr/local/lib/python3.11/site-packages/cosmos/operators/base.py", line 268, in execute
    self.build_and_run_cmd(context=context, cmd_flags=self.add_cmd_flags())
  File "/usr/local/lib/python3.11/site-packages/cosmos/operators/local.py", line 654, in build_and_run_cmd
    result = self.run_command(cmd=dbt_cmd, env=env, context=context)
             ^^^^^^^^^^^^^^^^^^^^^^^^^^^^^^^^^^^^^^^^^^^^^^^^^^^^^^^
  File "/usr/local/lib/python3.11/site-packages/cosmos/operators/local.py", line 509, in run_command
    self.handle_exception(result)
  File "/usr/local/lib/python3.11/site-packages/cosmos/operators/local.py", line 237, in handle_exception_dbt_runner
    raise AirflowException(f"dbt invocation completed with errors: {error_message}")
airflow.exceptions.AirflowException: dbt invocation completed with errors: stg_credit_fraud: Database Error in model stg_credit_fraud (models/staging/credit_fraud/stg_credit_fraud.sql)
  relation "dm_credit_operations_stage.raw_credit_fraud" does not exist
  LINE 8:     select * from "***"."dm_credit_operations_stage"...
                            ^
  compiled Code at target/run/***/models/staging/credit_fraud/stg_credit_fraud.sql
[2025-02-05T13:39:29.353+0000] {taskinstance.py:1206} INFO - Marking task as FAILED. dag_id=dag_dbt-model_credit_fraud, task_id=model_credit_fraud.stg_credit_fraud_run, run_id=scheduled__2025-02-04T04:00:00+00:00, execution_date=20250204T040000, start_date=20250205T133922, end_date=20250205T133929
[2025-02-05T13:39:29.369+0000] {standard_task_runner.py:110} ERROR - Failed to execute job 125 for task model_credit_fraud.stg_credit_fraud_run (dbt invocation completed with errors: stg_credit_fraud: Database Error in model stg_credit_fraud (models/staging/credit_fraud/stg_credit_fraud.sql)
  relation "dm_credit_operations_stage.raw_credit_fraud" does not exist
  LINE 8:     select * from "***"."dm_credit_operations_stage"...
                            ^
  compiled Code at target/run/***/models/staging/credit_fraud/stg_credit_fraud.sql; 4274)
[2025-02-05T13:39:29.422+0000] {local_task_job_runner.py:240} INFO - Task exited with return code 1
[2025-02-05T13:39:29.448+0000] {taskinstance.py:3498} INFO - 0 downstream tasks scheduled from follow-on schedule check
[2025-02-05T13:39:29.454+0000] {local_task_job_runner.py:222} INFO - ::endgroup::
