[2025-02-05T00:31:14.188+0000] {local_task_job_runner.py:120} INFO - ::group::Pre task execution logs
[2025-02-05T00:31:14.199+0000] {taskinstance.py:2076} INFO - Dependencies all met for dep_context=non-requeueable deps ti=<TaskInstance: dag_dbt-model_credit_fraud.model_credit_fraud.localiza_dw_test manual__2025-02-05T00:00:00+00:00 [queued]>
[2025-02-05T00:31:14.207+0000] {taskinstance.py:2076} INFO - Dependencies all met for dep_context=requeueable deps ti=<TaskInstance: dag_dbt-model_credit_fraud.model_credit_fraud.localiza_dw_test manual__2025-02-05T00:00:00+00:00 [queued]>
[2025-02-05T00:31:14.207+0000] {taskinstance.py:2306} INFO - Starting attempt 2 of 2
[2025-02-05T00:31:14.216+0000] {taskinstance.py:2330} INFO - Executing <Task(DbtTestLocalOperator): model_credit_fraud.localiza_dw_test> on 2025-02-05 00:00:00+00:00
[2025-02-05T00:31:14.221+0000] {standard_task_runner.py:63} INFO - Started process 1895 to run task
[2025-02-05T00:31:14.223+0000] {standard_task_runner.py:90} INFO - Running: ['***', 'tasks', 'run', 'dag_dbt-model_credit_fraud', 'model_credit_fraud.localiza_dw_test', 'manual__2025-02-05T00:00:00+00:00', '--job-id', '34', '--raw', '--subdir', 'DAGS_FOLDER/dag_dbt-model_fraud_credit.py', '--cfg-path', '/tmp/tmp8wb8apdu']
[2025-02-05T00:31:14.224+0000] {standard_task_runner.py:91} INFO - Job 34: Subtask model_credit_fraud.localiza_dw_test
[2025-02-05T00:31:14.270+0000] {task_command.py:426} INFO - Running <TaskInstance: dag_dbt-model_credit_fraud.model_credit_fraud.localiza_dw_test manual__2025-02-05T00:00:00+00:00 [running]> on host eb20c43aeeb4
[2025-02-05T00:31:14.346+0000] {taskinstance.py:2648} INFO - Exporting env vars: AIRFLOW_CTX_DAG_OWNER='***' AIRFLOW_CTX_DAG_ID='dag_dbt-model_credit_fraud' AIRFLOW_CTX_TASK_ID='model_credit_fraud.localiza_dw_test' AIRFLOW_CTX_EXECUTION_DATE='2025-02-05T00:00:00+00:00' AIRFLOW_CTX_TRY_NUMBER='2' AIRFLOW_CTX_DAG_RUN_ID='manual__2025-02-05T00:00:00+00:00'
[2025-02-05T00:31:14.349+0000] {taskinstance.py:430} INFO - ::endgroup::
[2025-02-05T00:31:16.269+0000] {local.py:220} INFO - dbtRunner is available. Using dbtRunner for invoking dbt.
[2025-02-05T00:31:16.270+0000] {local.py:436} INFO - Cloning project to writable temp directory /tmp/tmpnll4lbq3 from /usr/local/airflow/dags/dbt/localiza_dw
[2025-02-05T00:31:16.275+0000] {local.py:447} INFO - Partial parse is enabled and the latest partial parse file is /tmp/cosmos/dag_dbt-model_credit_fraud__model_credit_fraud/target/partial_parse.msgpack
[2025-02-05T00:31:16.278+0000] {config.py:348} INFO - Profile caching is enable.
[2025-02-05T00:31:16.293+0000] {base.py:84} INFO - Using connection ID '***' for task execution.
[2025-02-05T00:31:16.294+0000] {config.py:328} INFO - Profile found in cache using profile: /tmp/cosmos/profile/bdc35343eb23031ee554202b16407e794194afcc614f7ea62bc658c63495a211/profiles.yml.
[2025-02-05T00:31:16.295+0000] {local.py:408} INFO - Trying to run dbtRunner with:
 ['test', '--select', 'path:models/marts/credit_fraud path:models/staging/credit_fraud path:snapshots/credit_fraud', '--project-dir', '/tmp/tmpnll4lbq3', '--profiles-dir', '/tmp/cosmos/profile/bdc35343eb23031ee554202b16407e794194afcc614f7ea62bc658c63495a211', '--profile', '***', '--target', 'prod']
 in /tmp/tmpnll4lbq3
[2025-02-05T00:31:16.306+0000] {logging_mixin.py:188} INFO - 00:31:16  Running with dbt=1.6.1
[2025-02-05T00:31:16.386+0000] {logging_mixin.py:188} INFO - 00:31:16  Registered adapter: postgres=1.6.1
[2025-02-05T00:31:16.819+0000] {logging_mixin.py:188} INFO - 00:31:16  Found 3 models, 1 snapshot, 5 tests, 1 source, 0 exposures, 0 metrics, 349 macros, 0 groups, 0 semantic models
[2025-02-05T00:31:16.837+0000] {logging_mixin.py:188} INFO - 00:31:16
[2025-02-05T00:31:16.892+0000] {logging_mixin.py:188} INFO - 00:31:16  Concurrency: 1 threads (target='prod')
[2025-02-05T00:31:16.893+0000] {logging_mixin.py:188} INFO - 00:31:16
[2025-02-05T00:31:16.897+0000] {logging_mixin.py:188} INFO - 00:31:16  1 of 5 START test locations .................................................... [RUN]
[2025-02-05T00:31:16.942+0000] {logging_mixin.py:188} INFO - 00:31:16  1 of 5 PASS locations .......................................................... [PASS in 0.04s]
[2025-02-05T00:31:16.944+0000] {logging_mixin.py:188} INFO - 00:31:16  2 of 5 START test locations .................................................... [RUN]
[2025-02-05T00:31:16.969+0000] {logging_mixin.py:188} INFO - 00:31:16  2 of 5 ERROR locations ......................................................... [ERROR in 0.02s]
[2025-02-05T00:31:16.971+0000] {logging_mixin.py:188} INFO - 00:31:16  3 of 5 START test not_null_stg_credit_fraud_amount ............................. [RUN]
[2025-02-05T00:31:16.992+0000] {logging_mixin.py:188} INFO - 00:31:16  3 of 5 ERROR not_null_stg_credit_fraud_amount .................................. [ERROR in 0.02s]
[2025-02-05T00:31:16.994+0000] {logging_mixin.py:188} INFO - 00:31:16  4 of 5 START test not_null_stg_credit_fraud_risk_score ......................... [RUN]
[2025-02-05T00:31:17.013+0000] {logging_mixin.py:188} INFO - 00:31:17  4 of 5 ERROR not_null_stg_credit_fraud_risk_score .............................. [ERROR in 0.02s]
[2025-02-05T00:31:17.016+0000] {logging_mixin.py:188} INFO - 00:31:17  5 of 5 START test not_null_stg_credit_fraud_timestamp .......................... [RUN]
[2025-02-05T00:31:17.037+0000] {logging_mixin.py:188} INFO - 00:31:17  5 of 5 ERROR not_null_stg_credit_fraud_timestamp ............................... [ERROR in 0.02s]
[2025-02-05T00:31:17.049+0000] {logging_mixin.py:188} INFO - 00:31:17
[2025-02-05T00:31:17.051+0000] {logging_mixin.py:188} INFO - 00:31:17  Finished running 5 tests in 0 hours 0 minutes and 0.21 seconds (0.21s).
[2025-02-05T00:31:17.061+0000] {logging_mixin.py:188} INFO - 00:31:17
[2025-02-05T00:31:17.063+0000] {logging_mixin.py:188} INFO - 00:31:17  Completed with 4 errors and 0 warnings:
[2025-02-05T00:31:17.064+0000] {logging_mixin.py:188} INFO - 00:31:17
[2025-02-05T00:31:17.065+0000] {logging_mixin.py:188} INFO - 00:31:17  Database Error in test locations (models/staging/credit_fraud/schema.yml)
[2025-02-05T00:31:17.066+0000] {logging_mixin.py:188} INFO - 00:31:17    relation "dm_credit_operations.stg_credit_fraud" does not exist
[2025-02-05T00:31:17.066+0000] {logging_mixin.py:188} INFO - 00:31:17    LINE 17:     from "***"."dm_credit_operations"."stg_credit_fr...
[2025-02-05T00:31:17.067+0000] {logging_mixin.py:188} INFO - 00:31:17                      ^
[2025-02-05T00:31:17.068+0000] {logging_mixin.py:188} INFO - 00:31:17    compiled Code at target/run/***/models/staging/credit_fraud/schema.yml/locations.sql
[2025-02-05T00:31:17.068+0000] {logging_mixin.py:188} INFO - 00:31:17
[2025-02-05T00:31:17.069+0000] {logging_mixin.py:188} INFO - 00:31:17  Database Error in test not_null_stg_credit_fraud_amount (models/staging/credit_fraud/schema.yml)
[2025-02-05T00:31:17.070+0000] {logging_mixin.py:188} INFO - 00:31:17    relation "dm_credit_operations.stg_credit_fraud" does not exist
[2025-02-05T00:31:17.070+0000] {logging_mixin.py:188} INFO - 00:31:17    LINE 14: from "***"."dm_credit_operations"."stg_credit_fraud"
[2025-02-05T00:31:17.071+0000] {logging_mixin.py:188} INFO - 00:31:17                  ^
[2025-02-05T00:31:17.072+0000] {logging_mixin.py:188} INFO - 00:31:17    compiled Code at target/run/***/models/staging/credit_fraud/schema.yml/not_null_stg_credit_fraud_amount.sql
[2025-02-05T00:31:17.074+0000] {logging_mixin.py:188} INFO - 00:31:17
[2025-02-05T00:31:17.075+0000] {logging_mixin.py:188} INFO - 00:31:17  Database Error in test not_null_stg_credit_fraud_risk_score (models/staging/credit_fraud/schema.yml)
[2025-02-05T00:31:17.076+0000] {logging_mixin.py:188} INFO - 00:31:17    relation "dm_credit_operations.stg_credit_fraud" does not exist
[2025-02-05T00:31:17.077+0000] {logging_mixin.py:188} INFO - 00:31:17    LINE 14: from "***"."dm_credit_operations"."stg_credit_fraud"
[2025-02-05T00:31:17.078+0000] {logging_mixin.py:188} INFO - 00:31:17                  ^
[2025-02-05T00:31:17.079+0000] {logging_mixin.py:188} INFO - 00:31:17    compiled Code at target/run/***/models/staging/credit_fraud/schema.yml/not_null_stg_credit_fraud_risk_score.sql
[2025-02-05T00:31:17.080+0000] {logging_mixin.py:188} INFO - 00:31:17
[2025-02-05T00:31:17.081+0000] {logging_mixin.py:188} INFO - 00:31:17  Database Error in test not_null_stg_credit_fraud_timestamp (models/staging/credit_fraud/schema.yml)
[2025-02-05T00:31:17.082+0000] {logging_mixin.py:188} INFO - 00:31:17    relation "dm_credit_operations.stg_credit_fraud" does not exist
[2025-02-05T00:31:17.082+0000] {logging_mixin.py:188} INFO - 00:31:17    LINE 14: from "***"."dm_credit_operations"."stg_credit_fraud"
[2025-02-05T00:31:17.083+0000] {logging_mixin.py:188} INFO - 00:31:17                  ^
[2025-02-05T00:31:17.084+0000] {logging_mixin.py:188} INFO - 00:31:17    compiled Code at target/run/***/models/staging/credit_fraud/schema.yml/not_null_stg_credit_fraud_timestamp.sql
[2025-02-05T00:31:17.084+0000] {logging_mixin.py:188} INFO - 00:31:17
[2025-02-05T00:31:17.085+0000] {logging_mixin.py:188} INFO - 00:31:17  Done. PASS=1 WARN=0 ERROR=4 SKIP=0 TOTAL=5
[2025-02-05T00:31:17.827+0000] {local.py:138} WARNING - Artifact schema version: https://schemas.getdbt.com/dbt/manifest/v10.json is above dbt-ol supported version 7. This might cause errors.
[2025-02-05T00:31:17.854+0000] {local.py:494} INFO - Inlets: [Dataset(uri='postgres://postgres-db:5432/localiza_dw.dm_credit_operations.agg_locations_risk_score', extra=None), Dataset(uri='postgres://postgres-db:5432/localiza_dw.dm_credit_operations.stg_credit_fraud', extra=None)]
[2025-02-05T00:31:17.855+0000] {local.py:495} INFO - Outlets: []
[2025-02-05T00:31:17.856+0000] {local.py:595} INFO - Assigning inlets/outlets without DatasetAlias
[2025-02-05T00:31:17.857+0000] {dag.py:3096} INFO - Sync 1 DAGs
[2025-02-05T00:31:17.869+0000] {dag.py:3954} INFO - Setting next_dagrun for dag_dbt-model_credit_fraud to None, run_after=None
[2025-02-05T00:31:17.893+0000] {taskinstance.py:441} INFO - ::group::Post task execution logs
[2025-02-05T00:31:17.900+0000] {taskinstance.py:2905} ERROR - Task failed with exception
Traceback (most recent call last):
  File "/usr/local/lib/python3.11/site-packages/airflow/models/taskinstance.py", line 465, in _execute_task
    result = _execute_callable(context=context, **execute_callable_kwargs)
             ^^^^^^^^^^^^^^^^^^^^^^^^^^^^^^^^^^^^^^^^^^^^^^^^^^^^^^^^^^^^^
  File "/usr/local/lib/python3.11/site-packages/airflow/models/taskinstance.py", line 432, in _execute_callable
    return execute_callable(context=context, **execute_callable_kwargs)
           ^^^^^^^^^^^^^^^^^^^^^^^^^^^^^^^^^^^^^^^^^^^^^^^^^^^^^^^^^^^^
  File "/usr/local/lib/python3.11/site-packages/airflow/models/baseoperator.py", line 400, in wrapper
    return func(self, *args, **kwargs)
           ^^^^^^^^^^^^^^^^^^^^^^^^^^^
  File "/usr/local/lib/python3.11/site-packages/cosmos/operators/local.py", line 796, in execute
    result = self.build_and_run_cmd(context=context, cmd_flags=self.add_cmd_flags())
             ^^^^^^^^^^^^^^^^^^^^^^^^^^^^^^^^^^^^^^^^^^^^^^^^^^^^^^^^^^^^^^^^^^^^^^^
  File "/usr/local/lib/python3.11/site-packages/cosmos/operators/local.py", line 654, in build_and_run_cmd
    result = self.run_command(cmd=dbt_cmd, env=env, context=context)
             ^^^^^^^^^^^^^^^^^^^^^^^^^^^^^^^^^^^^^^^^^^^^^^^^^^^^^^^
  File "/usr/local/lib/python3.11/site-packages/cosmos/operators/local.py", line 509, in run_command
    self.handle_exception(result)
  File "/usr/local/lib/python3.11/site-packages/cosmos/operators/local.py", line 237, in handle_exception_dbt_runner
    raise AirflowException(f"dbt invocation completed with errors: {error_message}")
airflow.exceptions.AirflowException: dbt invocation completed with errors: locations: Database Error in test locations (models/staging/credit_fraud/schema.yml)
  relation "dm_credit_operations.stg_credit_fraud" does not exist
  LINE 17:     from "***"."dm_credit_operations"."stg_credit_fr...
                    ^
  compiled Code at target/run/***/models/staging/credit_fraud/schema.yml/locations.sql
not_null_stg_credit_fraud_amount: Database Error in test not_null_stg_credit_fraud_amount (models/staging/credit_fraud/schema.yml)
  relation "dm_credit_operations.stg_credit_fraud" does not exist
  LINE 14: from "***"."dm_credit_operations"."stg_credit_fraud"
                ^
  compiled Code at target/run/***/models/staging/credit_fraud/schema.yml/not_null_stg_credit_fraud_amount.sql
not_null_stg_credit_fraud_risk_score: Database Error in test not_null_stg_credit_fraud_risk_score (models/staging/credit_fraud/schema.yml)
  relation "dm_credit_operations.stg_credit_fraud" does not exist
  LINE 14: from "***"."dm_credit_operations"."stg_credit_fraud"
                ^
  compiled Code at target/run/***/models/staging/credit_fraud/schema.yml/not_null_stg_credit_fraud_risk_score.sql
not_null_stg_credit_fraud_timestamp: Database Error in test not_null_stg_credit_fraud_timestamp (models/staging/credit_fraud/schema.yml)
  relation "dm_credit_operations.stg_credit_fraud" does not exist
  LINE 14: from "***"."dm_credit_operations"."stg_credit_fraud"
                ^
  compiled Code at target/run/***/models/staging/credit_fraud/schema.yml/not_null_stg_credit_fraud_timestamp.sql
[2025-02-05T00:31:17.902+0000] {taskinstance.py:1206} INFO - Marking task as FAILED. dag_id=dag_dbt-model_credit_fraud, task_id=model_credit_fraud.***_test, run_id=manual__2025-02-05T00:00:00+00:00, execution_date=20250205T000000, start_date=20250205T003114, end_date=20250205T003117
[2025-02-05T00:31:17.909+0000] {standard_task_runner.py:110} ERROR - Failed to execute job 34 for task model_credit_fraud.***_test (dbt invocation completed with errors: locations: Database Error in test locations (models/staging/credit_fraud/schema.yml)
  relation "dm_credit_operations.stg_credit_fraud" does not exist
  LINE 17:     from "***"."dm_credit_operations"."stg_credit_fr...
                    ^
  compiled Code at target/run/***/models/staging/credit_fraud/schema.yml/locations.sql
not_null_stg_credit_fraud_amount: Database Error in test not_null_stg_credit_fraud_amount (models/staging/credit_fraud/schema.yml)
  relation "dm_credit_operations.stg_credit_fraud" does not exist
  LINE 14: from "***"."dm_credit_operations"."stg_credit_fraud"
                ^
  compiled Code at target/run/***/models/staging/credit_fraud/schema.yml/not_null_stg_credit_fraud_amount.sql
not_null_stg_credit_fraud_risk_score: Database Error in test not_null_stg_credit_fraud_risk_score (models/staging/credit_fraud/schema.yml)
  relation "dm_credit_operations.stg_credit_fraud" does not exist
  LINE 14: from "***"."dm_credit_operations"."stg_credit_fraud"
                ^
  compiled Code at target/run/***/models/staging/credit_fraud/schema.yml/not_null_stg_credit_fraud_risk_score.sql
not_null_stg_credit_fraud_timestamp: Database Error in test not_null_stg_credit_fraud_timestamp (models/staging/credit_fraud/schema.yml)
  relation "dm_credit_operations.stg_credit_fraud" does not exist
  LINE 14: from "***"."dm_credit_operations"."stg_credit_fraud"
                ^
  compiled Code at target/run/***/models/staging/credit_fraud/schema.yml/not_null_stg_credit_fraud_timestamp.sql; 1895)
[2025-02-05T00:31:17.956+0000] {local_task_job_runner.py:240} INFO - Task exited with return code 1
[2025-02-05T00:31:17.983+0000] {taskinstance.py:3498} INFO - 0 downstream tasks scheduled from follow-on schedule check
[2025-02-05T00:31:17.987+0000] {local_task_job_runner.py:222} INFO - ::endgroup::
