[2025-02-04T22:23:30.882+0000] {local_task_job_runner.py:120} INFO - ::group::Pre task execution logs
[2025-02-04T22:23:30.910+0000] {taskinstance.py:2076} INFO - Dependencies all met for dep_context=non-requeueable deps ti=<TaskInstance: dag_ingestion_daily-credit_fraud.bulk_file_load manual__2025-02-04T22:23:25.060591+00:00 [queued]>
[2025-02-04T22:23:30.928+0000] {taskinstance.py:2076} INFO - Dependencies all met for dep_context=requeueable deps ti=<TaskInstance: dag_ingestion_daily-credit_fraud.bulk_file_load manual__2025-02-04T22:23:25.060591+00:00 [queued]>
[2025-02-04T22:23:30.929+0000] {taskinstance.py:2306} INFO - Starting attempt 1 of 2
[2025-02-04T22:23:30.948+0000] {taskinstance.py:2330} INFO - Executing <Task(PostgresOperator): bulk_file_load> on 2025-02-04 22:23:25.060591+00:00
[2025-02-04T22:23:30.952+0000] {standard_task_runner.py:63} INFO - Started process 183 to run task
[2025-02-04T22:23:30.956+0000] {standard_task_runner.py:90} INFO - Running: ['***', 'tasks', 'run', 'dag_ingestion_daily-credit_fraud', 'bulk_file_load', 'manual__2025-02-04T22:23:25.060591+00:00', '--job-id', '3', '--raw', '--subdir', 'DAGS_FOLDER/dag_ingestion_daily-fraud_credit.py', '--cfg-path', '/tmp/tmpay5bg8_3']
[2025-02-04T22:23:30.958+0000] {standard_task_runner.py:91} INFO - Job 3: Subtask bulk_file_load
[2025-02-04T22:23:31.018+0000] {task_command.py:426} INFO - Running <TaskInstance: dag_ingestion_daily-credit_fraud.bulk_file_load manual__2025-02-04T22:23:25.060591+00:00 [running]> on host eb20c43aeeb4
[2025-02-04T22:23:31.084+0000] {taskinstance.py:2648} INFO - Exporting env vars: AIRFLOW_CTX_DAG_OWNER='***' AIRFLOW_CTX_DAG_ID='dag_ingestion_daily-credit_fraud' AIRFLOW_CTX_TASK_ID='bulk_file_load' AIRFLOW_CTX_EXECUTION_DATE='2025-02-04T22:23:25.060591+00:00' AIRFLOW_CTX_TRY_NUMBER='1' AIRFLOW_CTX_DAG_RUN_ID='manual__2025-02-04T22:23:25.060591+00:00'
[2025-02-04T22:23:31.086+0000] {taskinstance.py:430} INFO - ::endgroup::
[2025-02-04T22:23:31.097+0000] {sql.py:276} INFO - Executing: 
            COPY dm_credit_operations_stage.raw_credit_fraud FROM '/data/raw_fraud_credit.csv' DELIMITER ',' CSV HEADER;
        
[2025-02-04T22:23:31.103+0000] {taskinstance.py:441} INFO - ::group::Post task execution logs
[2025-02-04T22:23:31.110+0000] {taskinstance.py:2905} ERROR - Task failed with exception
Traceback (most recent call last):
  File "/usr/local/lib/python3.11/site-packages/airflow/models/taskinstance.py", line 465, in _execute_task
    result = _execute_callable(context=context, **execute_callable_kwargs)
             ^^^^^^^^^^^^^^^^^^^^^^^^^^^^^^^^^^^^^^^^^^^^^^^^^^^^^^^^^^^^^
  File "/usr/local/lib/python3.11/site-packages/airflow/models/taskinstance.py", line 432, in _execute_callable
    return execute_callable(context=context, **execute_callable_kwargs)
           ^^^^^^^^^^^^^^^^^^^^^^^^^^^^^^^^^^^^^^^^^^^^^^^^^^^^^^^^^^^^
  File "/usr/local/lib/python3.11/site-packages/airflow/models/baseoperator.py", line 400, in wrapper
    return func(self, *args, **kwargs)
           ^^^^^^^^^^^^^^^^^^^^^^^^^^^
  File "/usr/local/lib/python3.11/site-packages/airflow/providers/common/sql/operators/sql.py", line 277, in execute
    hook = self.get_db_hook()
           ^^^^^^^^^^^^^^^^^^
  File "/usr/local/lib/python3.11/site-packages/airflow/providers/common/sql/operators/sql.py", line 188, in get_db_hook
    return self._hook
           ^^^^^^^^^^
  File "/usr/local/lib/python3.11/functools.py", line 1001, in __get__
    val = self.func(instance)
          ^^^^^^^^^^^^^^^^^^^
  File "/usr/local/lib/python3.11/site-packages/airflow/providers/common/sql/operators/sql.py", line 150, in _hook
    conn = BaseHook.get_connection(conn_id)
           ^^^^^^^^^^^^^^^^^^^^^^^^^^^^^^^^
  File "/usr/local/lib/python3.11/site-packages/airflow/hooks/base.py", line 83, in get_connection
    conn = Connection.get_connection_from_secrets(conn_id)
           ^^^^^^^^^^^^^^^^^^^^^^^^^^^^^^^^^^^^^^^^^^^^^^^
  File "/usr/local/lib/python3.11/site-packages/airflow/models/connection.py", line 519, in get_connection_from_secrets
    raise AirflowNotFoundException(f"The conn_id `{conn_id}` isn't defined")
airflow.exceptions.AirflowNotFoundException: The conn_id `dm_credit_operations_stage` isn't defined
[2025-02-04T22:23:31.115+0000] {taskinstance.py:1206} INFO - Marking task as UP_FOR_RETRY. dag_id=dag_ingestion_daily-credit_fraud, task_id=bulk_file_load, run_id=manual__2025-02-04T22:23:25.060591+00:00, execution_date=20250204T222325, start_date=20250204T222330, end_date=20250204T222331
[2025-02-04T22:23:31.123+0000] {standard_task_runner.py:110} ERROR - Failed to execute job 3 for task bulk_file_load (The conn_id `dm_credit_operations_stage` isn't defined; 183)
[2025-02-04T22:23:31.133+0000] {local_task_job_runner.py:240} INFO - Task exited with return code 1
[2025-02-04T22:23:31.145+0000] {taskinstance.py:3498} INFO - 0 downstream tasks scheduled from follow-on schedule check
[2025-02-04T22:23:31.147+0000] {local_task_job_runner.py:222} INFO - ::endgroup::
