[2025-02-05T11:30:57.643+0000] {local_task_job_runner.py:120} INFO - ::group::Pre task execution logs
[2025-02-05T11:30:57.653+0000] {taskinstance.py:2076} INFO - Dependencies all met for dep_context=non-requeueable deps ti=<TaskInstance: dag_dbt-model_sales.model_sales.ad_hoc_avg_sales_run manual__2025-02-05T11:29:09+00:00 [queued]>
[2025-02-05T11:30:57.666+0000] {taskinstance.py:2076} INFO - Dependencies all met for dep_context=requeueable deps ti=<TaskInstance: dag_dbt-model_sales.model_sales.ad_hoc_avg_sales_run manual__2025-02-05T11:29:09+00:00 [queued]>
[2025-02-05T11:30:57.669+0000] {taskinstance.py:2306} INFO - Starting attempt 2 of 2
[2025-02-05T11:30:57.683+0000] {taskinstance.py:2330} INFO - Executing <Task(DbtRunLocalOperator): model_sales.ad_hoc_avg_sales_run> on 2025-02-05 11:29:09+00:00
[2025-02-05T11:30:57.686+0000] {standard_task_runner.py:63} INFO - Started process 1257 to run task
[2025-02-05T11:30:57.689+0000] {standard_task_runner.py:90} INFO - Running: ['***', 'tasks', 'run', 'dag_dbt-model_sales', 'model_sales.ad_hoc_avg_sales_run', 'manual__2025-02-05T11:29:09+00:00', '--job-id', '26', '--raw', '--subdir', 'DAGS_FOLDER/dag_dbt-model_sales.py', '--cfg-path', '/tmp/tmp4rlldhzk']
[2025-02-05T11:30:57.690+0000] {standard_task_runner.py:91} INFO - Job 26: Subtask model_sales.ad_hoc_avg_sales_run
[2025-02-05T11:30:57.733+0000] {task_command.py:426} INFO - Running <TaskInstance: dag_dbt-model_sales.model_sales.ad_hoc_avg_sales_run manual__2025-02-05T11:29:09+00:00 [running]> on host 98025f4a542d
[2025-02-05T11:30:57.797+0000] {taskinstance.py:2648} INFO - Exporting env vars: AIRFLOW_CTX_DAG_OWNER='***' AIRFLOW_CTX_DAG_ID='dag_dbt-model_sales' AIRFLOW_CTX_TASK_ID='model_sales.ad_hoc_avg_sales_run' AIRFLOW_CTX_EXECUTION_DATE='2025-02-05T11:29:09+00:00' AIRFLOW_CTX_TRY_NUMBER='2' AIRFLOW_CTX_DAG_RUN_ID='manual__2025-02-05T11:29:09+00:00'
[2025-02-05T11:30:57.800+0000] {taskinstance.py:430} INFO - ::endgroup::
[2025-02-05T11:30:59.378+0000] {local.py:220} INFO - dbtRunner is available. Using dbtRunner for invoking dbt.
[2025-02-05T11:30:59.379+0000] {local.py:436} INFO - Cloning project to writable temp directory /tmp/tmplmuwaoir from /usr/local/airflow/dags/dbt/localiza_dw
[2025-02-05T11:30:59.388+0000] {local.py:447} INFO - Partial parse is enabled and the latest partial parse file is /tmp/cosmos/dag_dbt-model_sales__model_sales/target/partial_parse.msgpack
[2025-02-05T11:30:59.393+0000] {config.py:348} INFO - Profile caching is enable.
[2025-02-05T11:30:59.399+0000] {base.py:84} INFO - Using connection ID '***' for task execution.
[2025-02-05T11:30:59.401+0000] {config.py:328} INFO - Profile found in cache using profile: /tmp/cosmos/profile/47873256e3df2d6067f929148b3671caee72f33396318ef25aae33418849eddf/profiles.yml.
[2025-02-05T11:30:59.402+0000] {local.py:408} INFO - Trying to run dbtRunner with:
 ['run', '--vars', '{"PROD_1": P003},                                {"DATA_INICIO": 1999-11-01},                                {"DATA_FIM": 2022-11-30}', '--models', 'ad_hoc_avg_sales', '--project-dir', '/tmp/tmplmuwaoir', '--profiles-dir', '/tmp/cosmos/profile/47873256e3df2d6067f929148b3671caee72f33396318ef25aae33418849eddf', '--profile', '***', '--target', 'prod']
 in /tmp/tmplmuwaoir
[2025-02-05T11:30:59.405+0000] {logging_mixin.py:188} INFO - 11:30:59  The YAML provided in the --vars argument is not valid.
[2025-02-05T11:30:59.416+0000] {local.py:138} WARNING - Artifact schema version: https://schemas.getdbt.com/dbt/manifest/v10.json is above dbt-ol supported version 7. This might cause errors.
[2025-02-05T11:30:59.417+0000] {local.py:494} INFO - Inlets: []
[2025-02-05T11:30:59.418+0000] {local.py:495} INFO - Outlets: []
[2025-02-05T11:30:59.419+0000] {local.py:595} INFO - Assigning inlets/outlets without DatasetAlias
[2025-02-05T11:30:59.419+0000] {dag.py:3096} INFO - Sync 1 DAGs
[2025-02-05T11:30:59.430+0000] {dag.py:3954} INFO - Setting next_dagrun for dag_dbt-model_sales to None, run_after=None
[2025-02-05T11:30:59.449+0000] {taskinstance.py:441} INFO - ::group::Post task execution logs
[2025-02-05T11:30:59.456+0000] {taskinstance.py:2905} ERROR - Task failed with exception
Traceback (most recent call last):
  File "/usr/local/lib/python3.11/site-packages/airflow/models/taskinstance.py", line 465, in _execute_task
    result = _execute_callable(context=context, **execute_callable_kwargs)
             ^^^^^^^^^^^^^^^^^^^^^^^^^^^^^^^^^^^^^^^^^^^^^^^^^^^^^^^^^^^^^
  File "/usr/local/lib/python3.11/site-packages/airflow/models/taskinstance.py", line 432, in _execute_callable
    return execute_callable(context=context, **execute_callable_kwargs)
           ^^^^^^^^^^^^^^^^^^^^^^^^^^^^^^^^^^^^^^^^^^^^^^^^^^^^^^^^^^^^
  File "/usr/local/lib/python3.11/site-packages/airflow/models/baseoperator.py", line 400, in wrapper
    return func(self, *args, **kwargs)
           ^^^^^^^^^^^^^^^^^^^^^^^^^^^
  File "/usr/local/lib/python3.11/site-packages/cosmos/operators/base.py", line 268, in execute
    self.build_and_run_cmd(context=context, cmd_flags=self.add_cmd_flags())
  File "/usr/local/lib/python3.11/site-packages/cosmos/operators/local.py", line 654, in build_and_run_cmd
    result = self.run_command(cmd=dbt_cmd, env=env, context=context)
             ^^^^^^^^^^^^^^^^^^^^^^^^^^^^^^^^^^^^^^^^^^^^^^^^^^^^^^^
  File "/usr/local/lib/python3.11/site-packages/cosmos/operators/local.py", line 509, in run_command
    self.handle_exception(result)
  File "/usr/local/lib/python3.11/site-packages/cosmos/operators/local.py", line 233, in handle_exception_dbt_runner
    raise AirflowException(f"dbt invocation did not complete with unhandled error: {result.exception}")
airflow.exceptions.AirflowException: dbt invocation did not complete with unhandled error: String '{"PROD_1": P003},                                {"DATA_INICIO": 1999-11-01},                                {"DATA_FIM": 2022-11-30}' is not valid YAML
[2025-02-05T11:30:59.458+0000] {taskinstance.py:1206} INFO - Marking task as FAILED. dag_id=dag_dbt-model_sales, task_id=model_sales.ad_hoc_avg_sales_run, run_id=manual__2025-02-05T11:29:09+00:00, execution_date=20250205T112909, start_date=20250205T113057, end_date=20250205T113059
[2025-02-05T11:30:59.465+0000] {standard_task_runner.py:110} ERROR - Failed to execute job 26 for task model_sales.ad_hoc_avg_sales_run (dbt invocation did not complete with unhandled error: String '{"PROD_1": P003},                                {"DATA_INICIO": 1999-11-01},                                {"DATA_FIM": 2022-11-30}' is not valid YAML; 1257)
[2025-02-05T11:30:59.476+0000] {local_task_job_runner.py:240} INFO - Task exited with return code 1
[2025-02-05T11:30:59.493+0000] {taskinstance.py:3498} INFO - 0 downstream tasks scheduled from follow-on schedule check
[2025-02-05T11:30:59.497+0000] {local_task_job_runner.py:222} INFO - ::endgroup::
