[2025-02-05T11:53:49.784+0000] {local_task_job_runner.py:120} INFO - ::group::Pre task execution logs
[2025-02-05T11:53:49.795+0000] {taskinstance.py:2076} INFO - Dependencies all met for dep_context=non-requeueable deps ti=<TaskInstance: dag_dbt-model_sales.model_sales.ad_hoc_vendedor_indicador_x_run manual__2025-02-05T11:53:16+00:00 [queued]>
[2025-02-05T11:53:49.801+0000] {taskinstance.py:2076} INFO - Dependencies all met for dep_context=requeueable deps ti=<TaskInstance: dag_dbt-model_sales.model_sales.ad_hoc_vendedor_indicador_x_run manual__2025-02-05T11:53:16+00:00 [queued]>
[2025-02-05T11:53:49.802+0000] {taskinstance.py:2306} INFO - Starting attempt 1 of 1
[2025-02-05T11:53:49.811+0000] {taskinstance.py:2330} INFO - Executing <Task(DbtRunLocalOperator): model_sales.ad_hoc_vendedor_indicador_x_run> on 2025-02-05 11:53:16+00:00
[2025-02-05T11:53:49.815+0000] {standard_task_runner.py:63} INFO - Started process 1946 to run task
[2025-02-05T11:53:49.817+0000] {standard_task_runner.py:90} INFO - Running: ['***', 'tasks', 'run', 'dag_dbt-model_sales', 'model_sales.ad_hoc_vendedor_indicador_x_run', 'manual__2025-02-05T11:53:16+00:00', '--job-id', '53', '--raw', '--subdir', 'DAGS_FOLDER/dag_dbt-model_sales.py', '--cfg-path', '/tmp/tmpeptju4ir']
[2025-02-05T11:53:49.818+0000] {standard_task_runner.py:91} INFO - Job 53: Subtask model_sales.ad_hoc_vendedor_indicador_x_run
[2025-02-05T11:53:49.854+0000] {task_command.py:426} INFO - Running <TaskInstance: dag_dbt-model_sales.model_sales.ad_hoc_vendedor_indicador_x_run manual__2025-02-05T11:53:16+00:00 [running]> on host 98025f4a542d
[2025-02-05T11:53:49.916+0000] {taskinstance.py:2648} INFO - Exporting env vars: AIRFLOW_CTX_DAG_OWNER='***' AIRFLOW_CTX_DAG_ID='dag_dbt-model_sales' AIRFLOW_CTX_TASK_ID='model_sales.ad_hoc_vendedor_indicador_x_run' AIRFLOW_CTX_EXECUTION_DATE='2025-02-05T11:53:16+00:00' AIRFLOW_CTX_TRY_NUMBER='1' AIRFLOW_CTX_DAG_RUN_ID='manual__2025-02-05T11:53:16+00:00'
[2025-02-05T11:53:49.920+0000] {taskinstance.py:430} INFO - ::endgroup::
[2025-02-05T11:53:51.561+0000] {local.py:220} INFO - dbtRunner is available. Using dbtRunner for invoking dbt.
[2025-02-05T11:53:51.563+0000] {local.py:436} INFO - Cloning project to writable temp directory /tmp/tmp_nvl5sy7 from /usr/local/airflow/dags/dbt/localiza_dw
[2025-02-05T11:53:51.568+0000] {local.py:447} INFO - Partial parse is enabled and the latest partial parse file is /tmp/cosmos/dag_dbt-model_sales__model_sales/target/partial_parse.msgpack
[2025-02-05T11:53:51.572+0000] {config.py:348} INFO - Profile caching is enable.
[2025-02-05T11:53:51.578+0000] {base.py:84} INFO - Using connection ID '***' for task execution.
[2025-02-05T11:53:51.579+0000] {config.py:328} INFO - Profile found in cache using profile: /tmp/cosmos/profile/47873256e3df2d6067f929148b3671caee72f33396318ef25aae33418849eddf/profiles.yml.
[2025-02-05T11:53:51.580+0000] {local.py:408} INFO - Trying to run dbtRunner with:
 ['run', '--vars', '{"PROD_1": P003,                                 "PROD_2": P002,                                 "DATA_INICIO": 1999-01-01,                                 "DATA_FIM": 2025-02-05}', '--models', 'ad_hoc_vendedor_indicador_x', '--project-dir', '/tmp/tmp_nvl5sy7', '--profiles-dir', '/tmp/cosmos/profile/47873256e3df2d6067f929148b3671caee72f33396318ef25aae33418849eddf', '--profile', '***', '--target', 'prod']
 in /tmp/tmp_nvl5sy7
[2025-02-05T11:53:51.591+0000] {logging_mixin.py:188} INFO - 11:53:51  Running with dbt=1.6.1
[2025-02-05T11:53:51.666+0000] {logging_mixin.py:188} INFO - 11:53:51  Registered adapter: postgres=1.6.1
[2025-02-05T11:53:52.042+0000] {logging_mixin.py:188} INFO - 11:53:52  Found 4 models, 1 snapshot, 4 seeds, 5 tests, 3 sources, 0 exposures, 0 metrics, 349 macros, 0 groups, 0 semantic models
[2025-02-05T11:53:52.044+0000] {logging_mixin.py:188} INFO - 11:53:52
[2025-02-05T11:53:52.099+0000] {logging_mixin.py:188} INFO - 11:53:52  Concurrency: 1 threads (target='prod')
[2025-02-05T11:53:52.101+0000] {logging_mixin.py:188} INFO - 11:53:52
[2025-02-05T11:53:52.104+0000] {logging_mixin.py:188} INFO - 11:53:52  1 of 1 START sql table model dm_sales.ad_hoc_vendedor_indicador_x .............. [RUN]
[2025-02-05T11:53:52.159+0000] {logging_mixin.py:188} INFO - 11:53:52  1 of 1 ERROR creating sql table model dm_sales.ad_hoc_vendedor_indicador_x ..... [ERROR in 0.05s]
[2025-02-05T11:53:52.171+0000] {logging_mixin.py:188} INFO - 11:53:52
[2025-02-05T11:53:52.172+0000] {logging_mixin.py:188} INFO - 11:53:52  Finished running 1 table model in 0 hours 0 minutes and 0.13 seconds (0.13s).
[2025-02-05T11:53:52.180+0000] {logging_mixin.py:188} INFO - 11:53:52
[2025-02-05T11:53:52.182+0000] {logging_mixin.py:188} INFO - 11:53:52  Completed with 1 error and 0 warnings:
[2025-02-05T11:53:52.183+0000] {logging_mixin.py:188} INFO - 11:53:52
[2025-02-05T11:53:52.184+0000] {logging_mixin.py:188} INFO - 11:53:52  Database Error in model ad_hoc_vendedor_indicador_x (models/marts/sales/ad_hoc_vendedor_indicador_x.sql)
[2025-02-05T11:53:52.186+0000] {logging_mixin.py:188} INFO - 11:53:52    syntax error at or near "FROM"
[2025-02-05T11:53:52.187+0000] {logging_mixin.py:188} INFO - 11:53:52    LINE 36: FROM "***"."dm_sales"."eventos_vendas" "v1"
[2025-02-05T11:53:52.187+0000] {logging_mixin.py:188} INFO - 11:53:52             ^
[2025-02-05T11:53:52.188+0000] {logging_mixin.py:188} INFO - 11:53:52    compiled Code at target/run/***/models/marts/sales/ad_hoc_vendedor_indicador_x.sql
[2025-02-05T11:53:52.189+0000] {logging_mixin.py:188} INFO - 11:53:52
[2025-02-05T11:53:52.189+0000] {logging_mixin.py:188} INFO - 11:53:52  Done. PASS=0 WARN=0 ERROR=1 SKIP=0 TOTAL=1
[2025-02-05T11:53:52.954+0000] {local.py:138} WARNING - Artifact schema version: https://schemas.getdbt.com/dbt/manifest/v10.json is above dbt-ol supported version 7. This might cause errors.
[2025-02-05T11:53:52.958+0000] {local.py:494} INFO - Inlets: []
[2025-02-05T11:53:52.959+0000] {local.py:495} INFO - Outlets: []
[2025-02-05T11:53:52.960+0000] {local.py:595} INFO - Assigning inlets/outlets without DatasetAlias
[2025-02-05T11:53:52.961+0000] {dag.py:3096} INFO - Sync 1 DAGs
[2025-02-05T11:53:52.971+0000] {dag.py:3954} INFO - Setting next_dagrun for dag_dbt-model_sales to None, run_after=None
[2025-02-05T11:53:52.997+0000] {taskinstance.py:441} INFO - ::group::Post task execution logs
[2025-02-05T11:53:53.003+0000] {taskinstance.py:2905} ERROR - Task failed with exception
Traceback (most recent call last):
  File "/usr/local/lib/python3.11/site-packages/airflow/models/taskinstance.py", line 465, in _execute_task
    result = _execute_callable(context=context, **execute_callable_kwargs)
             ^^^^^^^^^^^^^^^^^^^^^^^^^^^^^^^^^^^^^^^^^^^^^^^^^^^^^^^^^^^^^
  File "/usr/local/lib/python3.11/site-packages/airflow/models/taskinstance.py", line 432, in _execute_callable
    return execute_callable(context=context, **execute_callable_kwargs)
           ^^^^^^^^^^^^^^^^^^^^^^^^^^^^^^^^^^^^^^^^^^^^^^^^^^^^^^^^^^^^
  File "/usr/local/lib/python3.11/site-packages/airflow/models/baseoperator.py", line 400, in wrapper
    return func(self, *args, **kwargs)
           ^^^^^^^^^^^^^^^^^^^^^^^^^^^
  File "/usr/local/lib/python3.11/site-packages/cosmos/operators/base.py", line 268, in execute
    self.build_and_run_cmd(context=context, cmd_flags=self.add_cmd_flags())
  File "/usr/local/lib/python3.11/site-packages/cosmos/operators/local.py", line 654, in build_and_run_cmd
    result = self.run_command(cmd=dbt_cmd, env=env, context=context)
             ^^^^^^^^^^^^^^^^^^^^^^^^^^^^^^^^^^^^^^^^^^^^^^^^^^^^^^^
  File "/usr/local/lib/python3.11/site-packages/cosmos/operators/local.py", line 509, in run_command
    self.handle_exception(result)
  File "/usr/local/lib/python3.11/site-packages/cosmos/operators/local.py", line 237, in handle_exception_dbt_runner
    raise AirflowException(f"dbt invocation completed with errors: {error_message}")
airflow.exceptions.AirflowException: dbt invocation completed with errors: ad_hoc_vendedor_indicador_x: Database Error in model ad_hoc_vendedor_indicador_x (models/marts/sales/ad_hoc_vendedor_indicador_x.sql)
  syntax error at or near "FROM"
  LINE 36: FROM "***"."dm_sales"."eventos_vendas" "v1"
           ^
  compiled Code at target/run/***/models/marts/sales/ad_hoc_vendedor_indicador_x.sql
[2025-02-05T11:53:53.006+0000] {taskinstance.py:1206} INFO - Marking task as FAILED. dag_id=dag_dbt-model_sales, task_id=model_sales.ad_hoc_vendedor_indicador_x_run, run_id=manual__2025-02-05T11:53:16+00:00, execution_date=20250205T115316, start_date=20250205T115349, end_date=20250205T115353
[2025-02-05T11:53:53.013+0000] {standard_task_runner.py:110} ERROR - Failed to execute job 53 for task model_sales.ad_hoc_vendedor_indicador_x_run (dbt invocation completed with errors: ad_hoc_vendedor_indicador_x: Database Error in model ad_hoc_vendedor_indicador_x (models/marts/sales/ad_hoc_vendedor_indicador_x.sql)
  syntax error at or near "FROM"
  LINE 36: FROM "***"."dm_sales"."eventos_vendas" "v1"
           ^
  compiled Code at target/run/***/models/marts/sales/ad_hoc_vendedor_indicador_x.sql; 1946)
[2025-02-05T11:53:53.034+0000] {local_task_job_runner.py:240} INFO - Task exited with return code 1
[2025-02-05T11:53:53.054+0000] {taskinstance.py:3498} INFO - 0 downstream tasks scheduled from follow-on schedule check
[2025-02-05T11:53:53.059+0000] {local_task_job_runner.py:222} INFO - ::endgroup::
