[2025-02-04T22:56:31.882+0000] {local_task_job_runner.py:120} INFO - ::group::Pre task execution logs
[2025-02-04T22:56:31.895+0000] {taskinstance.py:2076} INFO - Dependencies all met for dep_context=non-requeueable deps ti=<TaskInstance: dag_dbt-model_credit_fraud.model_credit_fraud.stg_credit_fraud_run manual__2025-02-04T22:52:25.583411+00:00 [queued]>
[2025-02-04T22:56:31.900+0000] {taskinstance.py:2076} INFO - Dependencies all met for dep_context=requeueable deps ti=<TaskInstance: dag_dbt-model_credit_fraud.model_credit_fraud.stg_credit_fraud_run manual__2025-02-04T22:52:25.583411+00:00 [queued]>
[2025-02-04T22:56:31.901+0000] {taskinstance.py:2306} INFO - Starting attempt 2 of 2
[2025-02-04T22:56:31.909+0000] {taskinstance.py:2330} INFO - Executing <Task(DbtRunLocalOperator): model_credit_fraud.stg_credit_fraud_run> on 2025-02-04 22:52:25.583411+00:00
[2025-02-04T22:56:31.913+0000] {standard_task_runner.py:63} INFO - Started process 764 to run task
[2025-02-04T22:56:31.915+0000] {standard_task_runner.py:90} INFO - Running: ['***', 'tasks', 'run', 'dag_dbt-model_credit_fraud', 'model_credit_fraud.stg_credit_fraud_run', 'manual__2025-02-04T22:52:25.583411+00:00', '--job-id', '6', '--raw', '--subdir', 'DAGS_FOLDER/dag_dbt-model_fraud_credit.py', '--cfg-path', '/tmp/tmpaxzase2k']
[2025-02-04T22:56:31.916+0000] {standard_task_runner.py:91} INFO - Job 6: Subtask model_credit_fraud.stg_credit_fraud_run
[2025-02-04T22:56:31.954+0000] {task_command.py:426} INFO - Running <TaskInstance: dag_dbt-model_credit_fraud.model_credit_fraud.stg_credit_fraud_run manual__2025-02-04T22:52:25.583411+00:00 [running]> on host eb20c43aeeb4
[2025-02-04T22:56:32.014+0000] {taskinstance.py:2648} INFO - Exporting env vars: AIRFLOW_CTX_DAG_OWNER='***' AIRFLOW_CTX_DAG_ID='dag_dbt-model_credit_fraud' AIRFLOW_CTX_TASK_ID='model_credit_fraud.stg_credit_fraud_run' AIRFLOW_CTX_EXECUTION_DATE='2025-02-04T22:52:25.583411+00:00' AIRFLOW_CTX_TRY_NUMBER='2' AIRFLOW_CTX_DAG_RUN_ID='manual__2025-02-04T22:52:25.583411+00:00'
[2025-02-04T22:56:32.016+0000] {taskinstance.py:430} INFO - ::endgroup::
[2025-02-04T22:56:33.689+0000] {local.py:220} INFO - dbtRunner is available. Using dbtRunner for invoking dbt.
[2025-02-04T22:56:33.690+0000] {local.py:436} INFO - Cloning project to writable temp directory /tmp/tmpz6vk6oy2 from /usr/local/airflow/dags/dbt/localiza_dw
[2025-02-04T22:56:33.694+0000] {local.py:447} INFO - Partial parse is enabled and the latest partial parse file is /tmp/cosmos/dag_dbt-model_credit_fraud__model_credit_fraud/target/partial_parse.msgpack
[2025-02-04T22:56:33.699+0000] {config.py:348} INFO - Profile caching is enable.
[2025-02-04T22:56:33.705+0000] {base.py:84} INFO - Using connection ID '***' for task execution.
[2025-02-04T22:56:33.707+0000] {config.py:328} INFO - Profile found in cache using profile: /tmp/cosmos/profile/bdc35343eb23031ee554202b16407e794194afcc614f7ea62bc658c63495a211/profiles.yml.
[2025-02-04T22:56:33.707+0000] {local.py:408} INFO - Trying to run dbtRunner with:
 ['run', '--models', 'stg_credit_fraud', '--project-dir', '/tmp/tmpz6vk6oy2', '--profiles-dir', '/tmp/cosmos/profile/bdc35343eb23031ee554202b16407e794194afcc614f7ea62bc658c63495a211', '--profile', '***', '--target', 'prod']
 in /tmp/tmpz6vk6oy2
[2025-02-04T22:56:33.721+0000] {logging_mixin.py:188} INFO - 22:56:33  Running with dbt=1.6.1
[2025-02-04T22:56:33.816+0000] {logging_mixin.py:188} INFO - 22:56:33  Registered adapter: postgres=1.6.1
[2025-02-04T22:56:33.833+0000] {logging_mixin.py:188} INFO - 22:56:33  Unable to do partial parsing because profile has changed
[2025-02-04T22:56:33.835+0000] {logging_mixin.py:188} INFO - 22:56:33  Unable to do partial parsing because env vars used in profiles.yml have changed
[2025-02-04T22:56:34.589+0000] {logging_mixin.py:188} INFO - 22:56:34  Found 3 models, 1 snapshot, 5 tests, 1 source, 0 exposures, 0 metrics, 349 macros, 0 groups, 0 semantic models
[2025-02-04T22:56:34.591+0000] {logging_mixin.py:188} INFO - 22:56:34
[2025-02-04T22:56:34.643+0000] {logging_mixin.py:188} INFO - 22:56:34  Concurrency: 1 threads (target='prod')
[2025-02-04T22:56:34.644+0000] {logging_mixin.py:188} INFO - 22:56:34
[2025-02-04T22:56:34.647+0000] {logging_mixin.py:188} INFO - 22:56:34  1 of 1 START sql view model dm_credit_operations.stg_credit_fraud .............. [RUN]
[2025-02-04T22:56:34.689+0000] {logging_mixin.py:188} INFO - 22:56:34  1 of 1 ERROR creating sql view model dm_credit_operations.stg_credit_fraud ..... [ERROR in 0.04s]
[2025-02-04T22:56:34.700+0000] {logging_mixin.py:188} INFO - 22:56:34
[2025-02-04T22:56:34.701+0000] {logging_mixin.py:188} INFO - 22:56:34  Finished running 1 view model in 0 hours 0 minutes and 0.11 seconds (0.11s).
[2025-02-04T22:56:34.708+0000] {logging_mixin.py:188} INFO - 22:56:34
[2025-02-04T22:56:34.708+0000] {logging_mixin.py:188} INFO - 22:56:34  Completed with 1 error and 0 warnings:
[2025-02-04T22:56:34.709+0000] {logging_mixin.py:188} INFO - 22:56:34
[2025-02-04T22:56:34.709+0000] {logging_mixin.py:188} INFO - 22:56:34  Database Error in model stg_credit_fraud (models/staging/credit_fraud/stg_credit_fraud.sql)
[2025-02-04T22:56:34.710+0000] {logging_mixin.py:188} INFO - 22:56:34    relation "credit_fraud.raw_credit_fraud" does not exist
[2025-02-04T22:56:34.710+0000] {logging_mixin.py:188} INFO - 22:56:34    LINE 8:     select * from "***"."credit_fraud"."raw_credit_f...
[2025-02-04T22:56:34.711+0000] {logging_mixin.py:188} INFO - 22:56:34                              ^
[2025-02-04T22:56:34.711+0000] {logging_mixin.py:188} INFO - 22:56:34    compiled Code at target/run/***/models/staging/credit_fraud/stg_credit_fraud.sql
[2025-02-04T22:56:34.712+0000] {logging_mixin.py:188} INFO - 22:56:34
[2025-02-04T22:56:34.712+0000] {logging_mixin.py:188} INFO - 22:56:34  Done. PASS=0 WARN=0 ERROR=1 SKIP=0 TOTAL=1
[2025-02-04T22:56:35.433+0000] {local.py:138} WARNING - Artifact schema version: https://schemas.getdbt.com/dbt/manifest/v10.json is above dbt-ol supported version 7. This might cause errors.
[2025-02-04T22:56:35.436+0000] {local.py:494} INFO - Inlets: []
[2025-02-04T22:56:35.437+0000] {local.py:495} INFO - Outlets: []
[2025-02-04T22:56:35.438+0000] {local.py:595} INFO - Assigning inlets/outlets without DatasetAlias
[2025-02-04T22:56:35.439+0000] {dag.py:3096} INFO - Sync 1 DAGs
[2025-02-04T22:56:35.463+0000] {dag.py:3954} INFO - Setting next_dagrun for dag_dbt-model_credit_fraud to None, run_after=None
[2025-02-04T22:56:35.490+0000] {taskinstance.py:441} INFO - ::group::Post task execution logs
[2025-02-04T22:56:35.497+0000] {taskinstance.py:2905} ERROR - Task failed with exception
Traceback (most recent call last):
  File "/usr/local/lib/python3.11/site-packages/airflow/models/taskinstance.py", line 465, in _execute_task
    result = _execute_callable(context=context, **execute_callable_kwargs)
             ^^^^^^^^^^^^^^^^^^^^^^^^^^^^^^^^^^^^^^^^^^^^^^^^^^^^^^^^^^^^^
  File "/usr/local/lib/python3.11/site-packages/airflow/models/taskinstance.py", line 432, in _execute_callable
    return execute_callable(context=context, **execute_callable_kwargs)
           ^^^^^^^^^^^^^^^^^^^^^^^^^^^^^^^^^^^^^^^^^^^^^^^^^^^^^^^^^^^^
  File "/usr/local/lib/python3.11/site-packages/airflow/models/baseoperator.py", line 400, in wrapper
    return func(self, *args, **kwargs)
           ^^^^^^^^^^^^^^^^^^^^^^^^^^^
  File "/usr/local/lib/python3.11/site-packages/cosmos/operators/base.py", line 268, in execute
    self.build_and_run_cmd(context=context, cmd_flags=self.add_cmd_flags())
  File "/usr/local/lib/python3.11/site-packages/cosmos/operators/local.py", line 654, in build_and_run_cmd
    result = self.run_command(cmd=dbt_cmd, env=env, context=context)
             ^^^^^^^^^^^^^^^^^^^^^^^^^^^^^^^^^^^^^^^^^^^^^^^^^^^^^^^
  File "/usr/local/lib/python3.11/site-packages/cosmos/operators/local.py", line 509, in run_command
    self.handle_exception(result)
  File "/usr/local/lib/python3.11/site-packages/cosmos/operators/local.py", line 237, in handle_exception_dbt_runner
    raise AirflowException(f"dbt invocation completed with errors: {error_message}")
airflow.exceptions.AirflowException: dbt invocation completed with errors: stg_credit_fraud: Database Error in model stg_credit_fraud (models/staging/credit_fraud/stg_credit_fraud.sql)
  relation "credit_fraud.raw_credit_fraud" does not exist
  LINE 8:     select * from "***"."credit_fraud"."raw_credit_f...
                            ^
  compiled Code at target/run/***/models/staging/credit_fraud/stg_credit_fraud.sql
[2025-02-04T22:56:35.500+0000] {taskinstance.py:1206} INFO - Marking task as FAILED. dag_id=dag_dbt-model_credit_fraud, task_id=model_credit_fraud.stg_credit_fraud_run, run_id=manual__2025-02-04T22:52:25.583411+00:00, execution_date=20250204T225225, start_date=20250204T225631, end_date=20250204T225635
[2025-02-04T22:56:35.507+0000] {standard_task_runner.py:110} ERROR - Failed to execute job 6 for task model_credit_fraud.stg_credit_fraud_run (dbt invocation completed with errors: stg_credit_fraud: Database Error in model stg_credit_fraud (models/staging/credit_fraud/stg_credit_fraud.sql)
  relation "credit_fraud.raw_credit_fraud" does not exist
  LINE 8:     select * from "***"."credit_fraud"."raw_credit_f...
                            ^
  compiled Code at target/run/***/models/staging/credit_fraud/stg_credit_fraud.sql; 764)
[2025-02-04T22:56:35.548+0000] {local_task_job_runner.py:240} INFO - Task exited with return code 1
[2025-02-04T22:56:35.560+0000] {taskinstance.py:3498} INFO - 0 downstream tasks scheduled from follow-on schedule check
[2025-02-04T22:56:35.562+0000] {local_task_job_runner.py:222} INFO - ::endgroup::
