[2025-02-05T01:27:33.696+0000] {local_task_job_runner.py:120} INFO - ::group::Pre task execution logs
[2025-02-05T01:27:33.710+0000] {taskinstance.py:2076} INFO - Dependencies all met for dep_context=non-requeueable deps ti=<TaskInstance: dag_ingestion_daily-credit_fraud.create_table manual__2025-02-05T01:27:30.059909+00:00 [queued]>
[2025-02-05T01:27:33.717+0000] {taskinstance.py:2076} INFO - Dependencies all met for dep_context=requeueable deps ti=<TaskInstance: dag_ingestion_daily-credit_fraud.create_table manual__2025-02-05T01:27:30.059909+00:00 [queued]>
[2025-02-05T01:27:33.718+0000] {taskinstance.py:2306} INFO - Starting attempt 1 of 2
[2025-02-05T01:27:33.729+0000] {taskinstance.py:2330} INFO - Executing <Task(PostgresOperator): create_table> on 2025-02-05 01:27:30.059909+00:00
[2025-02-05T01:27:33.734+0000] {standard_task_runner.py:63} INFO - Started process 2371 to run task
[2025-02-05T01:27:33.738+0000] {standard_task_runner.py:90} INFO - Running: ['***', 'tasks', 'run', 'dag_ingestion_daily-credit_fraud', 'create_table', 'manual__2025-02-05T01:27:30.059909+00:00', '--job-id', '42', '--raw', '--subdir', 'DAGS_FOLDER/dag_ingestion_daily-fraud_credit.py', '--cfg-path', '/tmp/tmpkrmvnq7v']
[2025-02-05T01:27:33.740+0000] {standard_task_runner.py:91} INFO - Job 42: Subtask create_table
[2025-02-05T01:27:33.786+0000] {task_command.py:426} INFO - Running <TaskInstance: dag_ingestion_daily-credit_fraud.create_table manual__2025-02-05T01:27:30.059909+00:00 [running]> on host eb20c43aeeb4
[2025-02-05T01:27:33.865+0000] {taskinstance.py:2648} INFO - Exporting env vars: AIRFLOW_CTX_DAG_OWNER='***' AIRFLOW_CTX_DAG_ID='dag_ingestion_daily-credit_fraud' AIRFLOW_CTX_TASK_ID='create_table' AIRFLOW_CTX_EXECUTION_DATE='2025-02-05T01:27:30.059909+00:00' AIRFLOW_CTX_TRY_NUMBER='1' AIRFLOW_CTX_DAG_RUN_ID='manual__2025-02-05T01:27:30.059909+00:00'
[2025-02-05T01:27:33.867+0000] {taskinstance.py:430} INFO - ::endgroup::
[2025-02-05T01:27:33.882+0000] {sql.py:276} INFO - Executing: 
            DROP TABLE IF EXISTS dm_credit_operations_stage_.raw_credit_fraud CASCADE;
            CREATE TABLE dm_credit_operations_stage_.raw_credit_fraud (
               timestamp VARCHAR(50) NULL,
               sending_address VARCHAR(50) NULL,
               receiving_address VARCHAR(50) NULL,
               amount VARCHAR(50) NULL,
               transaction_type VARCHAR(50) NULL,
               location_region VARCHAR(50) NULL,
               ip_prefix VARCHAR(50) NULL,
               login_frequency VARCHAR(50) NULL,
               session_duration VARCHAR(50) NULL,
               purchase_pattern VARCHAR(50) NULL,
               age_group VARCHAR(50) NULL,
               risk_score VARCHAR(50) NULL,
               anomaly VARCHAR(50) NULL
          );
        
[2025-02-05T01:27:33.890+0000] {base.py:84} INFO - Using connection ID '***' for task execution.
[2025-02-05T01:27:33.938+0000] {base.py:84} INFO - Using connection ID '***' for task execution.
[2025-02-05T01:27:33.944+0000] {sql.py:450} INFO - Running statement: 
            DROP TABLE IF EXISTS dm_credit_operations_stage_.raw_credit_fraud CASCADE;
            CREATE TABLE dm_credit_operations_stage_.raw_credit_fraud (
               timestamp VARCHAR(50) NULL,
               sending_address VARCHAR(50) NULL,
               receiving_address VARCHAR(50) NULL,
               amount VARCHAR(50) NULL,
               transaction_type VARCHAR(50) NULL,
               location_region VARCHAR(50) NULL,
               ip_prefix VARCHAR(50) NULL,
               login_frequency VARCHAR(50) NULL,
               session_duration VARCHAR(50) NULL,
               purchase_pattern VARCHAR(50) NULL,
               age_group VARCHAR(50) NULL,
               risk_score VARCHAR(50) NULL,
               anomaly VARCHAR(50) NULL
          );
        , parameters: None
[2025-02-05T01:27:33.946+0000] {taskinstance.py:441} INFO - ::group::Post task execution logs
[2025-02-05T01:27:33.947+0000] {taskinstance.py:2905} ERROR - Task failed with exception
Traceback (most recent call last):
  File "/usr/local/lib/python3.11/site-packages/airflow/models/taskinstance.py", line 465, in _execute_task
    result = _execute_callable(context=context, **execute_callable_kwargs)
             ^^^^^^^^^^^^^^^^^^^^^^^^^^^^^^^^^^^^^^^^^^^^^^^^^^^^^^^^^^^^^
  File "/usr/local/lib/python3.11/site-packages/airflow/models/taskinstance.py", line 432, in _execute_callable
    return execute_callable(context=context, **execute_callable_kwargs)
           ^^^^^^^^^^^^^^^^^^^^^^^^^^^^^^^^^^^^^^^^^^^^^^^^^^^^^^^^^^^^
  File "/usr/local/lib/python3.11/site-packages/airflow/models/baseoperator.py", line 400, in wrapper
    return func(self, *args, **kwargs)
           ^^^^^^^^^^^^^^^^^^^^^^^^^^^
  File "/usr/local/lib/python3.11/site-packages/airflow/providers/common/sql/operators/sql.py", line 282, in execute
    output = hook.run(
             ^^^^^^^^^
  File "/usr/local/lib/python3.11/site-packages/airflow/providers/common/sql/hooks/sql.py", line 398, in run
    self._run_command(cur, sql_statement, parameters)
  File "/usr/local/lib/python3.11/site-packages/airflow/providers/common/sql/hooks/sql.py", line 455, in _run_command
    cur.execute(sql_statement)
psycopg2.errors.InvalidSchemaName: schema "dm_credit_operations_stage_" does not exist
LINE 3:             CREATE TABLE dm_credit_operations_stage_.raw_cre...
                                 ^

[2025-02-05T01:27:33.956+0000] {taskinstance.py:1206} INFO - Marking task as UP_FOR_RETRY. dag_id=dag_ingestion_daily-credit_fraud, task_id=create_table, run_id=manual__2025-02-05T01:27:30.059909+00:00, execution_date=20250205T012730, start_date=20250205T012733, end_date=20250205T012733
[2025-02-05T01:27:33.966+0000] {standard_task_runner.py:110} ERROR - Failed to execute job 42 for task create_table (schema "dm_credit_operations_stage_" does not exist
LINE 3:             CREATE TABLE dm_credit_operations_stage_.raw_cre...
                                 ^
; 2371)
[2025-02-05T01:27:33.997+0000] {local_task_job_runner.py:240} INFO - Task exited with return code 1
[2025-02-05T01:27:34.017+0000] {taskinstance.py:3498} INFO - 0 downstream tasks scheduled from follow-on schedule check
[2025-02-05T01:27:34.021+0000] {local_task_job_runner.py:222} INFO - ::endgroup::
