[2025-02-05T16:09:59.594+0000] {local_task_job_runner.py:120} INFO - ::group::Pre task execution logs
[2025-02-05T16:09:59.612+0000] {taskinstance.py:2076} INFO - Dependencies all met for dep_context=non-requeueable deps ti=<TaskInstance: dag_dbt-model_sales.model_sales.ad_hoc_sales_growth_run manual__2025-02-05T16:09:14+00:00 [queued]>
[2025-02-05T16:09:59.624+0000] {taskinstance.py:2076} INFO - Dependencies all met for dep_context=requeueable deps ti=<TaskInstance: dag_dbt-model_sales.model_sales.ad_hoc_sales_growth_run manual__2025-02-05T16:09:14+00:00 [queued]>
[2025-02-05T16:09:59.625+0000] {taskinstance.py:2306} INFO - Starting attempt 1 of 1
[2025-02-05T16:09:59.639+0000] {taskinstance.py:2330} INFO - Executing <Task(DbtRunLocalOperator): model_sales.ad_hoc_sales_growth_run> on 2025-02-05 16:09:14+00:00
[2025-02-05T16:09:59.644+0000] {standard_task_runner.py:63} INFO - Started process 835 to run task
[2025-02-05T16:09:59.647+0000] {standard_task_runner.py:90} INFO - Running: ['***', 'tasks', 'run', 'dag_dbt-model_sales', 'model_sales.ad_hoc_sales_growth_run', 'manual__2025-02-05T16:09:14+00:00', '--job-id', '20', '--raw', '--subdir', 'DAGS_FOLDER/dag_dbt-model_sales.py', '--cfg-path', '/tmp/tmp9vtjjegs']
[2025-02-05T16:09:59.648+0000] {standard_task_runner.py:91} INFO - Job 20: Subtask model_sales.ad_hoc_sales_growth_run
[2025-02-05T16:09:59.709+0000] {task_command.py:426} INFO - Running <TaskInstance: dag_dbt-model_sales.model_sales.ad_hoc_sales_growth_run manual__2025-02-05T16:09:14+00:00 [running]> on host 5c897c3a2254
[2025-02-05T16:09:59.803+0000] {taskinstance.py:2648} INFO - Exporting env vars: AIRFLOW_CTX_DAG_OWNER='***' AIRFLOW_CTX_DAG_ID='dag_dbt-model_sales' AIRFLOW_CTX_TASK_ID='model_sales.ad_hoc_sales_growth_run' AIRFLOW_CTX_EXECUTION_DATE='2025-02-05T16:09:14+00:00' AIRFLOW_CTX_TRY_NUMBER='1' AIRFLOW_CTX_DAG_RUN_ID='manual__2025-02-05T16:09:14+00:00'
[2025-02-05T16:09:59.805+0000] {taskinstance.py:430} INFO - ::endgroup::
[2025-02-05T16:10:02.865+0000] {local.py:220} INFO - dbtRunner is available. Using dbtRunner for invoking dbt.
[2025-02-05T16:10:02.867+0000] {local.py:436} INFO - Cloning project to writable temp directory /tmp/tmpnb1h_2ca from /usr/local/airflow/dags/dbt/localiza_dw
[2025-02-05T16:10:02.873+0000] {local.py:447} INFO - Partial parse is enabled and the latest partial parse file is /tmp/cosmos/dag_dbt-model_sales__model_sales/target/partial_parse.msgpack
[2025-02-05T16:10:02.881+0000] {config.py:348} INFO - Profile caching is enable.
[2025-02-05T16:10:02.895+0000] {base.py:84} INFO - Using connection ID '***' for task execution.
[2025-02-05T16:10:02.897+0000] {config.py:328} INFO - Profile found in cache using profile: /tmp/cosmos/profile/47873256e3df2d6067f929148b3671caee72f33396318ef25aae33418849eddf/profiles.yml.
[2025-02-05T16:10:02.898+0000] {local.py:408} INFO - Trying to run dbtRunner with:
 ['run', '--vars', '{"PROD": "P003", "LIMITE_QUANTIDADE": "500", "DATA_INICIO": "1999-01-01", "DATA_FIM": "2025-02-05"}', '--models', 'ad_hoc_sales_growth', '--project-dir', '/tmp/tmpnb1h_2ca', '--profiles-dir', '/tmp/cosmos/profile/47873256e3df2d6067f929148b3671caee72f33396318ef25aae33418849eddf', '--profile', '***', '--target', 'prod']
 in /tmp/tmpnb1h_2ca
[2025-02-05T16:10:02.923+0000] {logging_mixin.py:188} INFO - 16:10:02  Running with dbt=1.6.1
[2025-02-05T16:10:03.080+0000] {logging_mixin.py:188} INFO - 16:10:03  Registered adapter: postgres=1.6.1
[2025-02-05T16:10:03.826+0000] {logging_mixin.py:188} INFO - 16:10:03  Found 5 models, 1 snapshot, 4 seeds, 5 tests, 3 sources, 0 exposures, 0 metrics, 349 macros, 0 groups, 0 semantic models
[2025-02-05T16:10:03.829+0000] {logging_mixin.py:188} INFO - 16:10:03
[2025-02-05T16:10:03.908+0000] {logging_mixin.py:188} INFO - 16:10:03  Concurrency: 1 threads (target='prod')
[2025-02-05T16:10:03.909+0000] {logging_mixin.py:188} INFO - 16:10:03
[2025-02-05T16:10:03.915+0000] {logging_mixin.py:188} INFO - 16:10:03  1 of 1 START sql table model dm_sales.ad_hoc_sales_growth ...................... [RUN]
[2025-02-05T16:10:03.982+0000] {logging_mixin.py:188} INFO - 16:10:03  1 of 1 ERROR creating sql table model dm_sales.ad_hoc_sales_growth ............. [ERROR in 0.07s]
[2025-02-05T16:10:03.995+0000] {logging_mixin.py:188} INFO - 16:10:03
[2025-02-05T16:10:03.996+0000] {logging_mixin.py:188} INFO - 16:10:03  Finished running 1 table model in 0 hours 0 minutes and 0.16 seconds (0.16s).
[2025-02-05T16:10:04.006+0000] {logging_mixin.py:188} INFO - 16:10:04
[2025-02-05T16:10:04.007+0000] {logging_mixin.py:188} INFO - 16:10:04  Completed with 1 error and 0 warnings:
[2025-02-05T16:10:04.008+0000] {logging_mixin.py:188} INFO - 16:10:04
[2025-02-05T16:10:04.009+0000] {logging_mixin.py:188} INFO - 16:10:04  Database Error in model ad_hoc_sales_growth (models/marts/sales/ad_hoc_sales_growth.sql)
[2025-02-05T16:10:04.010+0000] {logging_mixin.py:188} INFO - 16:10:04    syntax error at or near ";"
[2025-02-05T16:10:04.011+0000] {logging_mixin.py:188} INFO - 16:10:04    LINE 31:            END) = 0;
[2025-02-05T16:10:04.013+0000] {logging_mixin.py:188} INFO - 16:10:04                                ^
[2025-02-05T16:10:04.014+0000] {logging_mixin.py:188} INFO - 16:10:04    compiled Code at target/run/***/models/marts/sales/ad_hoc_sales_growth.sql
[2025-02-05T16:10:04.015+0000] {logging_mixin.py:188} INFO - 16:10:04
[2025-02-05T16:10:04.016+0000] {logging_mixin.py:188} INFO - 16:10:04  Done. PASS=0 WARN=0 ERROR=1 SKIP=0 TOTAL=1
[2025-02-05T16:10:05.018+0000] {local.py:138} WARNING - Artifact schema version: https://schemas.getdbt.com/dbt/manifest/v10.json is above dbt-ol supported version 7. This might cause errors.
[2025-02-05T16:10:05.021+0000] {local.py:494} INFO - Inlets: []
[2025-02-05T16:10:05.022+0000] {local.py:495} INFO - Outlets: []
[2025-02-05T16:10:05.022+0000] {local.py:595} INFO - Assigning inlets/outlets without DatasetAlias
[2025-02-05T16:10:05.023+0000] {dag.py:3096} INFO - Sync 1 DAGs
[2025-02-05T16:10:05.041+0000] {dag.py:3954} INFO - Setting next_dagrun for dag_dbt-model_sales to 2025-02-05 04:00:00+00:00, run_after=2025-02-06 04:00:00+00:00
[2025-02-05T16:10:05.071+0000] {taskinstance.py:441} INFO - ::group::Post task execution logs
[2025-02-05T16:10:05.078+0000] {taskinstance.py:2905} ERROR - Task failed with exception
Traceback (most recent call last):
  File "/usr/local/lib/python3.11/site-packages/airflow/models/taskinstance.py", line 465, in _execute_task
    result = _execute_callable(context=context, **execute_callable_kwargs)
             ^^^^^^^^^^^^^^^^^^^^^^^^^^^^^^^^^^^^^^^^^^^^^^^^^^^^^^^^^^^^^
  File "/usr/local/lib/python3.11/site-packages/airflow/models/taskinstance.py", line 432, in _execute_callable
    return execute_callable(context=context, **execute_callable_kwargs)
           ^^^^^^^^^^^^^^^^^^^^^^^^^^^^^^^^^^^^^^^^^^^^^^^^^^^^^^^^^^^^
  File "/usr/local/lib/python3.11/site-packages/airflow/models/baseoperator.py", line 400, in wrapper
    return func(self, *args, **kwargs)
           ^^^^^^^^^^^^^^^^^^^^^^^^^^^
  File "/usr/local/lib/python3.11/site-packages/cosmos/operators/base.py", line 268, in execute
    self.build_and_run_cmd(context=context, cmd_flags=self.add_cmd_flags())
  File "/usr/local/lib/python3.11/site-packages/cosmos/operators/local.py", line 654, in build_and_run_cmd
    result = self.run_command(cmd=dbt_cmd, env=env, context=context)
             ^^^^^^^^^^^^^^^^^^^^^^^^^^^^^^^^^^^^^^^^^^^^^^^^^^^^^^^
  File "/usr/local/lib/python3.11/site-packages/cosmos/operators/local.py", line 509, in run_command
    self.handle_exception(result)
  File "/usr/local/lib/python3.11/site-packages/cosmos/operators/local.py", line 237, in handle_exception_dbt_runner
    raise AirflowException(f"dbt invocation completed with errors: {error_message}")
airflow.exceptions.AirflowException: dbt invocation completed with errors: ad_hoc_sales_growth: Database Error in model ad_hoc_sales_growth (models/marts/sales/ad_hoc_sales_growth.sql)
  syntax error at or near ";"
  LINE 31:            END) = 0;
                              ^
  compiled Code at target/run/***/models/marts/sales/ad_hoc_sales_growth.sql
[2025-02-05T16:10:05.083+0000] {taskinstance.py:1206} INFO - Marking task as FAILED. dag_id=dag_dbt-model_sales, task_id=model_sales.ad_hoc_sales_growth_run, run_id=manual__2025-02-05T16:09:14+00:00, execution_date=20250205T160914, start_date=20250205T160959, end_date=20250205T161005
[2025-02-05T16:10:05.093+0000] {standard_task_runner.py:110} ERROR - Failed to execute job 20 for task model_sales.ad_hoc_sales_growth_run (dbt invocation completed with errors: ad_hoc_sales_growth: Database Error in model ad_hoc_sales_growth (models/marts/sales/ad_hoc_sales_growth.sql)
  syntax error at or near ";"
  LINE 31:            END) = 0;
                              ^
  compiled Code at target/run/***/models/marts/sales/ad_hoc_sales_growth.sql; 835)
[2025-02-05T16:10:05.107+0000] {local_task_job_runner.py:240} INFO - Task exited with return code 1
[2025-02-05T16:10:05.124+0000] {taskinstance.py:3498} INFO - 0 downstream tasks scheduled from follow-on schedule check
[2025-02-05T16:10:05.128+0000] {local_task_job_runner.py:222} INFO - ::endgroup::
